<?xml version="1.0" encoding="utf-8"?>

<robot
  name="humanoid">
  <link
    name="base">
    <inertial>
      <origin
        xyz="0.009598 0.000935 0.151714"
        rpy="0 0 0" />
      <mass
        value="7.954054" />
      <inertia
        ixx="0.168459"
        ixy="0.000124"
        ixz="0.006493"
        iyy="0.101358"
        iyz="0.000278"
        izz="0.091754" />
    </inertial>
    <visual>
      <origin
        xyz="-0.00565 0 -0.05735"
        rpy="0 0 0" />
      <geometry>
        <mesh
          filename="meshes_v4/torso_scaled.dae"/>
      </geometry>
    </visual>
    <collision>
      <origin
        xyz="-0.00565 0 -0.05735"
        rpy="0 0 0" />
      <geometry>
        <mesh
          filename="meshes_v4/torso_scaled.dae"/>
      </geometry>
    </collision>
  </link>



<!-- Right Leg -->
 
 <link
    name="right_hip_yaw">
    <inertial>
      <origin
        xyz="-0.065362  0.000128  -0.063947"
        rpy="0 0 0" />
      <mass
        value=" 0.842752" />
      <inertia
        ixx="0.001502 "
        ixy="-0.000004 "
        ixz="-0.000533"
        iyy="0.001361 "
        iyz="0.000000"
        izz="0.001170" />
    </inertial>
    <visual>
      <origin
        xyz="0 0 0"
        rpy="0 0 0" />
      <geometry>
        <mesh
          filename="meshes_v4/right_hip_yaw_scaled.dae" />
      </geometry>
    </visual>
    <collision>
      <origin
        xyz="0 0 0"
        rpy="0 0 0" />
      <geometry>
        <mesh
          filename="meshes_v4/right_hip_yaw_scaled.dae" />
      </geometry>
    </collision>
  </link>
  <joint
    name="right_hip_yaw_joint"
    type="revolute">
    <origin
      xyz="-0.00565 -0.082 -0.05735"
      rpy="0 -0.174533 0" />
    <parent
      link="base" />
    <child
      link="right_hip_yaw" />
    <axis
      xyz="0 0 1" />
    <limit effort="34" lower="-6.28" upper="6.28" velocity="50"/>
    <!-- <dynamics damping="0.0" friction="0.0" rotor_inertia="0.01188"/> -->
  </joint>
  
  <link
    name="right_hip_abad">
    <inertial>
      <origin
        xyz=" 0.067579  0.013035 0.000132"
        rpy="0 0 0" />
      <mass
        value="1.199631" />
      <inertia
        ixx="0.001745 "
        ixy="-0.000003 "
        ixz=" 0.000082"
        iyy="0.003338 "
        iyz=" -0.000010 "
        izz=" 0.001951" />
    </inertial>
    <visual>
      <origin
        xyz="0 0 0"
        rpy="0 0 0" />
      <geometry>
        <mesh
          filename="meshes_v4/right_hip_abad_scaled.dae"/>
      </geometry>
    </visual>
    <collision>
      <origin
        xyz="0 0 0"
        rpy="0 0 0" />
      <geometry>
        <mesh
          filename="meshes_v4/right_hip_abad_scaled.dae"/>
      </geometry>
    </collision>
  </link>
  <joint
    name="right_hip_abad_joint"
    type="revolute">
    <origin
      xyz="-0.06435 0 -.07499"
      rpy="0.0 0.436332 0.0"/>
    <parent
      link="right_hip_yaw" />
    <child
      link="right_hip_abad" />
    <axis
      xyz="-1 0 0" />
          <limit effort="34" lower="-6.28" upper="6.28" velocity="50"/>
    <!-- <dynamics damping="0.0" friction="0.0" rotor_inertia="0.01188"/> -->
  </joint>
  
 <link
    name="right_upper_leg">
    <inertial>
      <origin
        xyz=" -0.001100  -0.026032 -0.078842"
        rpy="0 0 0" />
      <mass
        value="2.634789" />
      <inertia
        ixx="0.024489 "
        ixy="-0.000068 "
        ixz=" -0.000512 "
        iyy="0.026049 "
        iyz="0.002657 "
        izz="0.003812 " />
    </inertial>
    <visual>
      <origin
        xyz="0.01283 0 -0.0174"
        rpy="0 0 0" />
      <geometry>
        <mesh
          filename="meshes_v4/right_leg_upper_scaled.dae" />
      </geometry>
    </visual>
    <collision>
      <origin
        xyz="0.01283 0 -0.0174"
        rpy="0 0 0" />
      <geometry>
        <mesh
          filename="meshes_v4/right_leg_upper_scaled.dae" />
      </geometry>
    </collision>
  </link>
  <joint
    name="right_hip_pitch_joint"
    type="revolute">
    <origin
      xyz="0.07133 0.002 0.0"
      rpy="0 -0.261799 0" />
    <parent
      link="right_hip_abad" />
    <child
      link="right_upper_leg" />
    <axis
      xyz="0 1 0" />
          <limit effort="72" lower="-6.28" upper="6.28" velocity="50"/>
    <!-- <dynamics damping="0.0" friction="0.0" rotor_inertia="0.0198"/> -->
  </joint>
  
  <link
    name="right_lower_leg">
    <inertial>
      <origin
        xyz="0.005232 -0.000457  -0.131581"
        rpy="0 0 0" />
      <mass
        value="0.346291" />
      <inertia
        ixx=" 0.002952 "
        ixy=" 0.0"
        ixz=" -0.000083"
        iyy=" 0.002943"
        iyz=" 0.000033"
        izz=" 0.000238" />
    </inertial>
    <visual>
      <origin
        xyz="0 0 0"
        rpy="0 0 0" />
      <geometry>
        <mesh
          filename="meshes_v4/right_leg_lower_scaled.dae" />
      </geometry>
    </visual>
    <collision>
      <origin
        xyz="0 0 0"
        rpy="0 0 0" />
      <geometry>
        <mesh
          filename="meshes_v4/right_leg_lower_scaled.dae" />
      </geometry>
    </collision>
  </link>
  <joint
    name="right_knee_joint"
    type="revolute">
    <origin
      xyz="0.0 0.0 -0.2666"
      rpy="0 0 0" />
    <parent
      link="right_upper_leg" />
    <child
      link="right_lower_leg" />
    <axis
      xyz="0 1 0" />
          <limit effort="144" lower="0." upper="3." velocity="50"/>
    <!-- <dynamics damping="0.0" friction="0.0" rotor_inertia="0.0792"/> -->
  </joint>
  
   <link
    name="right_foot">
    <inertial>
      <origin
        xyz="0.022696 0.0 -0.013879 "
        rpy="0 0 0" />
      <mass
        value=" 0.279583" />
      <inertia
        ixx="0.000092"
        ixy="0.0"
        ixz="0.000054 "
        iyy="0.000806 "
        iyz="0.0 "
        izz="0.000769" />
    </inertial>
    <visual>
      <origin
        xyz="0 0 0"
        rpy="0 0 0" />
      <geometry>
        <mesh
          filename="meshes_v4/right_foot_scaled.dae"/>
      </geometry>

    </visual>
    <collision>
      <origin
        xyz="0 0 0"
        rpy="0 0 0" />
      <geometry>
        <mesh
          filename="meshes_v4/right_foot_scaled.dae"/>
      </geometry>

    </collision>
  </link>
  <joint
    name="right_ankle_joint"
    type="revolute">
    <origin
      xyz="0.0 0.0 -0.2785"
      rpy="0 0 0" />
    <parent
      link="right_lower_leg" />
    <child
      link="right_foot" />
    <axis
      xyz="0 1 0" />
          <limit effort="68" lower="-1.5" upper="1.5" velocity="50"/>
    <!-- <dynamics damping="0.0" friction="0.0" rotor_inertia="0.04752"/> -->
  </joint>

  <!-- Add fixed links at toe and heel -->
  <link
    name="right_toe">
  </link>

  <link
    name="right_heel">
  </link>

  <joint
    name="right_toe_joint"
    type="fixed">
    <origin
      xyz="0.1 0 -.041"
      rpy="0 0 0" />
    <parent
      link="right_foot" />
    <child
      link="right_toe" />
  </joint>

  <joint
    name="right_heel_joint"
    type="fixed">
    <origin
      xyz="-0.05 0 -.041"
      rpy="0 0 0" />
    <parent
      link="right_foot" />
    <child
      link="right_heel" />
  </joint>


  <!--    Left leg-->
  <link
    name="left_hip_yaw">
    <inertial>
      <origin
        xyz="-0.065362  -0.000128  -0.063947"
        rpy="0 0 0" />
      <mass
        value=" 0.842752" />
      <inertia
        ixx="0.001502 "
        ixy="0.000004 "
        ixz="0.000533"
        iyy="0.001361 "
        iyz="0.000000"
        izz="0.001170" />
    </inertial>
    <visual>
      <origin
        xyz="0 0 0"
        rpy="0 0 0" />
      <geometry>
        <mesh
          filename="meshes_v4/left_hip_yaw_scaled.dae" />
      </geometry>
    </visual>
        <collision>
      <origin
        xyz="0 0 0"
        rpy="0 0 0" />
      <geometry>
        <mesh
          filename="meshes_v4/left_hip_yaw_scaled.dae" />
      </geometry>
    </collision>
  </link>
  <joint
    name="left_hip_yaw_joint"
    type="revolute">
    <origin
      xyz="-0.00565 0.082 -0.05735"
      rpy="0 -0.174533 0" />
    <parent
      link="base" />
    <child
      link="left_hip_yaw" />
    <axis
      xyz="0 0 -1" />
    <!-- <limit effort="34" lower="-6.28" upper="6.28" velocity="50"/> -->
    <!-- <dynamics damping="0.0" friction="0.0" rotor_inertia="0.01188"/> -->
  </joint>
  <link
    name="left_hip_abad">
    <inertial>
      <origin
        xyz=" 0.067579  -0.013035 0.000132"
        rpy="0 0 0" />
      <mass
        value="1.199631" />
      <inertia
        ixx="0.001745 "
        ixy="0.000003 "
        ixz=" -0.000082"
        iyy="0.003338 "
        iyz=" -0.000010 "
        izz=" 0.001951" />
    </inertial>
    <visual>
      <origin
        xyz="0 0 0"
        rpy="0 0 0" />
      <geometry>
        <mesh
          filename="meshes_v4/left_hip_abad_scaled.dae"/>
      </geometry>
    </visual>
    <collision>
      <origin
        xyz="0 0 0"
        rpy="0 0 0" />
      <geometry>
        <mesh
          filename="meshes_v4/left_hip_abad_scaled.dae"/>
      </geometry>
    </collision>
  </link>
  <joint
    name="left_hip_abad_joint"
    type="revolute">
    <origin
      xyz="-0.06435 0 -.07499"
      rpy="0.0 0.436332 0.0"/>
    <parent
      link="left_hip_yaw" />
    <child
      link="left_hip_abad" />
    <axis
      xyz="1 0 0" />
          <!-- <limit effort="34" lower="-6.28" upper="6.28" velocity="50"/> -->
    <!-- <dynamics damping="0.0" friction="0.0" rotor_inertia="0.01188"/> -->
  </joint>
 <link 
    name="left_upper_leg">
    <inertial>
      <origin
        xyz=" -0.001100  0.026032 -0.078842"
        rpy="0 0 0" />
      <mass
        value="2.634789" />
      <inertia
        ixx="0.024489 "
        ixy="0.000068 "
        ixz=" 0.000512 "
        iyy="0.026049 "
        iyz="0.002657 "
        izz="0.003812 " />
    </inertial>
    <visual>
      <origin
        xyz="0.01283 0 -0.0174"
        rpy="0 0 0" />
      <geometry>
        <mesh
          filename="meshes_v4/left_leg_upper_scaled.dae" />
      </geometry>
    </visual>
    <collision>
      <origin
        xyz="0.01283 0 -0.0174"
        rpy="0 0 0" />
      <geometry>
        <mesh
          filename="meshes_v4/left_leg_upper_scaled.dae" />
      </geometry>
    </collision>
  </link>
  <joint
    name="left_hip_pitch_joint"
    type="revolute">
    <origin
      xyz="0.07133 -0.002 0.0"
      rpy="0 -0.261799 0" />
    <parent
      link="left_hip_abad" />
    <child
      link="left_upper_leg" />
    <axis
      xyz="0 1 0" />
          <limit effort="72" lower="-6.28" upper="6.28" velocity="50"/>
    <!-- <dynamics damping="0.0" friction="0.0" rotor_inertia="0.0198"/> -->
  </joint>
  
  <link
    name="left_lower_leg">
    <inertial>
      <origin
        xyz="0.005232 0.000457  -0.131581"
        rpy="0 0 0" />
      <mass
        value="0.346291" />
      <inertia
        ixx=" 0.002952 "
        ixy=" 0.0"
        ixz=" 0.000083"
        iyy=" 0.002943"
        iyz=" 0.000033"
        izz=" 0.000238" />
    </inertial>
    <visual>
      <origin
        xyz="0 0 0"
        rpy="0 0 0" />
      <geometry>
        <mesh
          filename="meshes_v4/left_leg_lower_scaled.dae" />
      </geometry>
    </visual>
    <collision>
      <origin
        xyz="0 0 0"
        rpy="0 0 0" />
      <geometry>
        <mesh
          filename="meshes_v4/left_leg_lower_scaled.dae" />
      </geometry>
    </collision>
  </link>
  <joint
    name="left_knee_joint"
    type="revolute">
    <origin
      xyz="0.0 0.0 -0.2666"
      rpy="0 0 0" />
    <parent
      link="left_upper_leg" />
    <child
      link="left_lower_leg" />
    <axis
      xyz="0 1 0" />
          <limit effort="144" lower="0." upper="3." velocity="50"/>
    <!-- <dynamics damping="0.0" friction="0.0" rotor_inertia="0.0792"/> -->
  </joint>
  
   <link
    name="left_foot">
    <inertial>
      <origin
        xyz="0.022696 0.0 -0.013879 "
        rpy="0 0 0" />
      <mass
        value=" 0.279583" />
      <inertia
        ixx="0.000092"
        ixy="0.0"
        ixz="-0.000054 "
        iyy="0.000806 "
        iyz="0.0 "
        izz="0.000769" />
    </inertial>
    <visual>
      <origin
        xyz="0 0 0"
        rpy="0 0 0" />
      <geometry>
        <mesh
          filename="meshes_v4/left_foot_scaled.dae"/>
      </geometry>
    </visual>
    <collision>
      <origin
        xyz="0 0 0"
        rpy="0 0 0" />
      <geometry>
        <mesh
          filename="meshes_v4/left_foot_scaled.dae"/>
      </geometry>
    </collision>
  </link>
  <joint
    name="left_ankle_joint"
    type="revolute">
    <origin
      xyz="0.0 0.0 -0.2785"
      rpy="0 0 0" />
    <parent
      link="left_lower_leg" />
    <child
      link="left_foot" />
    <axis
      xyz="0 1 0" />
          <limit effort="68" lower="-1.5" upper="1.5" velocity="50"/>
    <!-- <dynamics damping="0.0" friction="0.0" rotor_inertia="0.04752"/> -->
  </joint>

  <!-- Add fixed links at toe and heel -->
  <link
    name="left_toe">
  </link>

  <link
    name="left_heel">
  </link>

  <joint
    name="left_toe"
    type="fixed">
    <origin
      xyz="0.1 0 -.041"
      rpy="0 0 0" />
    <parent
      link="left_foot" />
    <child
      link="left_toe" />
  </joint>

  <joint
    name="left_heel"
    type="fixed">
    <origin
      xyz="-0.05 0 -.041"
      rpy="0 0 0" />
    <parent
      link="left_foot" />
    <child
      link="left_heel" />
  </joint>




  <!-- Right Arm -->
  <link
    name="right_shoulder">
    <inertial>
      <origin
        xyz="0.009518 -0.053027 0.000060"
        rpy="0 0 0" />
      <mass
        value="0.788506" />
      <inertia
        ixx="0.001363 "
        ixy="-0.000024 "
        ixz=" 0.000002 "
        iyy="0.000759 "
        iyz="  0.000001"
        izz="  0.000866" />
    </inertial>
    <visual>
      <origin
        xyz="0 0 0"
        rpy="0 0 0" />
      <geometry>
        <mesh
          filename="meshes_v4/right_shoulder1_scaled.dae"/>
      </geometry>

    </visual>
    <collision>
      <origin
        xyz="0 0 0"
        rpy="0 0 0" />
      <geometry>
        <mesh
          filename="meshes_v4/right_shoulder1_scaled.dae"/>
      </geometry>

    </collision>
  </link>
  <joint
    name="right_arm_pitch"
    type="revolute">
    <origin
      xyz="0.01346 -0.17608 0.24657"
      rpy="0 0 0" />
    <parent
      link="base" />
    <child
      link="right_shoulder" />
    <axis
      xyz="0 1 0" />
          <limit effort="34" lower="-6.28" upper="6.28" velocity="50"/>
    <!-- <dynamics damping="0.0" friction="0.0" rotor_inertia="0.01188"/> -->
  </joint>
  
  <link
    name="right_shoulder_2">
    <inertial>
      <origin
        xyz="0.000117 -0.000122 -0.082758"
        rpy="0 0 0" />
      <mass
        value="0.801249" />
      <inertia
        ixx=" 0.001136 "
        ixy="-0.000001 "
        ixz="-0.000016 "
        iyy="0.001175 "
        iyz=" 0.000001 "
        izz="0.001241 " />
    </inertial>
    <visual>
      <origin
        xyz="0 0 0"
        rpy="0 0 0" />
      <geometry>
        <mesh
          filename="meshes_v4/right_shoulder2_scaled.dae"/>
      </geometry>

    </visual>
    <collision>
      <origin
        xyz="0 0 0"
        rpy="0 0 0" />
      <geometry>
        <mesh
          filename="meshes_v4/right_shoulder2_scaled.dae"/>
      </geometry>

    </collision>
  </link>
  <joint
    name="right_shoulder_abad"
    type="revolute">
    <origin
      xyz="0 -.05760 0"
      rpy="0.0 0 0" />
    <parent
      link="right_shoulder" />
    <child
      link="right_shoulder_2" />
    <axis
      xyz="-1 0 0" />
        <limit effort="34" lower="-6.28" upper="6.28" velocity="50"/>
    <!-- <dynamics damping="0.0" friction="0.0" rotor_inertia="0.01188"/> -->
  </joint>
  <!--  -->
  
  <link
    name="right_upper_arm">
    <inertial>
      <origin
        xyz="-0.000073 0.016471  -0.063210"
        rpy="0 0 0" />
      <mass
        value="0.905588" />
      <inertia
        ixx=" 0.001353 "
        ixy="-0.000002 "
        ixz="-0.000001 "
        iyy="0.001804 "
        iyz="-0.000061 "
        izz="0.000796 " />
    </inertial>
    <visual>
      <origin
        xyz="0 0 0"
        rpy="0 0 0" />
      <geometry>
        <mesh
          filename="meshes_v4/right_shoulder3_scaled.dae"/>
      </geometry>

    </visual>
    <collision>
      <origin
        xyz="0 0 0"
        rpy="0 0 0" />
      <geometry>
        <mesh
          filename="meshes_v4/right_shoulder3_scaled.dae"/>
      </geometry>

    </collision>
  </link>
  <joint
    name="right_shoulder_yaw"
    type="revolute">
    <origin
      xyz="0 0 -.10250"
      rpy="0.0 0 0" />
    <parent
      link="right_shoulder_2" />
    <child
      link="right_upper_arm" />
    <axis
      xyz="0 0 1" />
        <limit effort="34" lower="-6.28" upper="6.28" velocity="50"/>
    <!-- <dynamics damping="0.0" friction="0.0" rotor_inertia="0.01188"/> -->
  </joint>

  
  <link
    name="right_lower_arm">
    <inertial>
      <origin
        xyz="-0.007103 -0.000073 -0.099203"
        rpy="0 0 0" />
      <mass
        value="0.348390" />
      <inertia
        ixx="0.003400 "
        ixy="0.0 "
        ixz="-0.000049 "
        iyy="0.003453 "
        iyz="-0.000002 "
        izz="0.000078 " />
    </inertial>
    <visual>
      <origin
        xyz="0 0 0"
        rpy="0 0 0" />
      <geometry>
        <mesh
          filename="meshes_v4/left_forearm_scaled.dae"/>
      </geometry>

    </visual>
    <collision>
      <origin
        xyz="0 0 0"
        rpy="0 0 0" />
      <geometry>
        <mesh
          filename="meshes_v4/left_forearm_scaled.dae"/>
      </geometry>

    </collision>
  </link>
  <joint
    name="right_elbow"
    type="revolute">
    <origin
      xyz="0 0 -.15750"
      rpy="0 0 0.0" />
    <parent
      link="right_upper_arm" />
    <child
      link="right_lower_arm" />
    <axis
      xyz="0 1 0" />
        <limit effort="55" lower="-6.28" upper="6.28" velocity="50"/>
    <!-- <dynamics damping="0.0" friction="0.0" rotor_inertia="0.0304"/> -->
  </joint>

  

  <!-- Left Arm -->
  <link
    name="left_shoulder"> <!--      shoulder Ry-->
    <inertial>
      <origin
        xyz="0.009518 0.053027 0.000060"
        rpy="0 0 0" />
      <mass
        value="0.788506" />
      <inertia
        ixx="0.001363 "
        ixy="0.000024 "
        ixz=" -0.000002 "
        iyy="0.000759 "
        iyz="  0.000001"
        izz="  0.000866" />
    </inertial>
    <visual>
      <origin
        xyz="0 0 0"
        rpy="0 0 0" />
      <geometry>
        <mesh
          filename="meshes_v4/left_shoulder1_scaled.dae"/>
      </geometry>

    </visual>
    <collision>
      <origin
        xyz="0 0 0"
        rpy="0 0 0" />
      <geometry>
        <mesh
          filename="meshes_v4/left_shoulder1_scaled.dae"/>
      </geometry>

    </collision>
  </link>
  <joint
    name="left_arm_pitch"
    type="revolute">
    <origin
      xyz="0.01346 0.17608 0.24657"
      rpy="0 0 0" />
    <parent
      link="base" />
    <child
      link="left_shoulder" />
    <axis
      xyz="0 1 0" />
          <limit effort="34" lower="-6.28" upper="6.28" velocity="50"/>
    <!-- <dynamics damping="0.0" friction="0.0" rotor_inertia="0.01188"/> -->
  </joint>
  
  <link
    name="left_shoulder_2"> <!--      shoulder Rx-->
    <inertial>
      <origin
        xyz="0.000117 0.000122 -0.082758"
        rpy="0 0 0" />
      <mass
        value="0.801249" />
      <inertia
        ixx=" 0.001136 "
        ixy="0.000001 "
        ixz="0.000016 "
        iyy="0.001175 "
        iyz=" 0.000001 "
        izz="0.001241 " />
    </inertial>
    <visual>
      <origin
        xyz="0 0 0"
        rpy="0 0 0" />
      <geometry>
        <mesh
          filename="meshes_v4/left_shoulder2_scaled.dae"/>
      </geometry>

    </visual>
    <collision>
      <origin
        xyz="0 0 0"
        rpy="0 0 0" />
      <geometry>
        <mesh
          filename="meshes_v4/left_shoulder2_scaled.dae"/>
      </geometry>

    </collision>
  </link>
  <joint
    name="left_shoulder_abad"
    type="revolute">
    <origin
      xyz="0 .05760 0"
      rpy="0.0 0 0" />
    <parent
      link="left_shoulder" />
    <child
      link="left_shoulder_2" />
    <axis
      xyz="1 0 0" />
        <limit effort="34" lower="-6.28" upper="6.28" velocity="50"/>
    <!-- <dynamics damping="0.0" friction="0.0" rotor_inertia="0.01188"/> -->
  </joint>
  <!--  -->
  
  <link
    name="left_upper_arm">  <!--      shoulder Rz-->
    <inertial>
      <origin
        xyz="-0.000073 -0.016471  -0.063210"
        rpy="0 0 0" />
      <mass
        value="0.905588" />
      <inertia
        ixx=" 0.001353 "
        ixy="0.000002 "
        ixz="0.000001 "
        iyy="0.001804 "
        iyz="-0.000061 "
        izz="0.000796 " />
    </inertial>
    <visual>
      <origin
        xyz="0 0 0"
        rpy="0 0 0" />
      <geometry>
        <mesh
          filename="meshes_v4/left_shoulder3_scaled.dae"/>
      </geometry>

    </visual>
    <collision>
      <origin
        xyz="0 0 0"
        rpy="0 0 0" />
      <geometry>
        <mesh
          filename="meshes_v4/left_shoulder3_scaled.dae"/>
      </geometry>

    </collision>
  </link>
  <joint
    name="left_shoulder_yaw"
    type="revolute">
    <origin
      xyz="0 0 -.10250"
      rpy="0.0 0 0" />
    <parent
      link="left_shoulder_2" />
    <child
      link="left_upper_arm" />
    <axis
      xyz="0 0 -1" />
        <limit effort="34" lower="-6.28" upper="6.28" velocity="50"/>
    <!-- <dynamics damping="0.0" friction="0.0" rotor_inertia="0.01188"/> -->
  </joint>
  
  <link
    name="left_lower_arm">
    <inertial>
      <origin
        xyz="-0.007103 -0.000073 -0.099203"
        rpy="0 0 0" />
      <mass
        value="0.348390" />
      <inertia
        ixx="0.003400 "
        ixy="0.0 "
        ixz="-0.000049 "
        iyy="0.003453 "
        iyz="-0.000002 "
        izz="0.000078 " />
    </inertial>
    <visual>
      <origin
        xyz="0 0 0"
        rpy="0 0 0" />
      <geometry>
        <mesh
          filename="meshes_v4/left_forearm_scaled.dae"/>
      </geometry>

    </visual>
    <collision>
      <origin
        xyz="0 0 0"
        rpy="0 0 0" />
      <geometry>
        <mesh
          filename="meshes_v4/left_forearm_scaled.dae"/>
      </geometry>

    </collision>
  </link>
  <joint
    name="left_elbow"
    type="revolute">
    <origin
      xyz="0 0 -.15750"
      rpy="0 0 0.0" />
    <parent
      link="left_upper_arm" />
    <child
      link="left_lower_arm" />
    <axis
      xyz="0 1 0" />
        <limit effort="55" lower="-6.28" upper="6.28" velocity="50"/>
    <!-- <dynamics damping="0.0" friction="0.0" rotor_inertia="0.0304"/> -->
  </joint>


</robot>